2020-08-21 04:49:44,284 INFO    MainThread:27020 [wandb_init.py:_log_setup():292] Logging user logs to wandb\run-20200821_044944-31dgho99\logs\debug-20200821_044944-31dgho99.log
2020-08-21 04:49:44,284 INFO    MainThread:27020 [wandb_init.py:_log_setup():293] Logging internal logs to wandb\run-20200821_044944-31dgho99\logs\debug-internal-20200821_044944-31dgho99.log
2020-08-21 04:49:44,284 INFO    MainThread:27020 [wandb_setup.py:_flush():68] setting env: {}
2020-08-21 04:49:44,284 INFO    MainThread:27020 [wandb_setup.py:_flush():68] multiprocessing start_methods=spawn
2020-08-21 04:49:47,218 INFO    MainThread:27020 [wandb_run.py:_console_start():882] atexit reg
2020-08-21 04:49:47,218 INFO    MainThread:27020 [wandb_run.py:_redirect():792] redirect: off
2020-08-21 04:51:05,882 INFO    MainThread:27020 [wandb_run.py:_atexit_cleanup():866] got exitcode: 1
2020-08-21 04:51:05,884 INFO    MainThread:27020 [wandb_run.py:_wait_for_finish():951] got exit ret: uuid: "a920fcfb5e8e4ba2900f50640418d377"
response {
  poll_exit_response {
    file_counts {
      wandb_count: 1
    }
    pusher_stats {
      uploaded_bytes: 713
      total_bytes: 713
    }
  }
}

2020-08-21 04:51:07,901 INFO    MainThread:27020 [wandb_run.py:_wait_for_finish():951] got exit ret: uuid: "7d5ac2948ddf4a22b2a9b64086bdd3e3"
response {
  poll_exit_response {
    file_counts {
      wandb_count: 3
    }
    pusher_stats {
      uploaded_bytes: 7527
      total_bytes: 7527
    }
  }
}

2020-08-21 04:51:09,912 INFO    MainThread:27020 [wandb_run.py:_wait_for_finish():951] got exit ret: uuid: "aeed4a785ade4dbc87b70cf77707d516"
response {
  poll_exit_response {
    done: true
    exit_result {
    }
    file_counts {
      wandb_count: 3
    }
    pusher_stats {
      uploaded_bytes: 7527
      total_bytes: 7527
    }
  }
}

2020-08-21 04:51:09,914 INFO    MainThread:27020 [wandb_run.py:_restore():838] restore
2020-08-21 04:51:11,945 INFO    MainThread:27020 [wandb_run.py:_on_final():1018] logging synced files
2020-08-21 04:51:11,948 INFO    MainThread:27020 [internal.py:handle_exit():49] Process exited cleanly
